Traceback (most recent call last):
  File "/usr/share/miniconda3/envs/docbuild/lib/python3.10/site-packages/jupyter_cache/executors/utils.py", line 58, in single_nb_execution
    executenb(
  File "/usr/share/miniconda3/envs/docbuild/lib/python3.10/site-packages/nbclient/client.py", line 1305, in execute
    return NotebookClient(nb=nb, resources=resources, km=km, **kwargs).execute()
  File "/usr/share/miniconda3/envs/docbuild/lib/python3.10/site-packages/jupyter_core/utils/__init__.py", line 162, in wrapped
    return loop.run_until_complete(inner)
  File "/usr/share/miniconda3/envs/docbuild/lib/python3.10/asyncio/base_events.py", line 649, in run_until_complete
    return future.result()
  File "/usr/share/miniconda3/envs/docbuild/lib/python3.10/site-packages/nbclient/client.py", line 705, in async_execute
    await self.async_execute_cell(
  File "/usr/share/miniconda3/envs/docbuild/lib/python3.10/site-packages/nbclient/client.py", line 1058, in async_execute_cell
    await self._check_raise_for_error(cell, cell_index, exec_reply)
  File "/usr/share/miniconda3/envs/docbuild/lib/python3.10/site-packages/nbclient/client.py", line 914, in _check_raise_for_error
    raise CellExecutionError.from_cell_and_msg(cell, exec_reply_content)
nbclient.exceptions.CellExecutionError: An error occurred while executing the following cell:
------------------
state.report.histogram(
    table_name="persons", 
    column_name="distance_to_school",
)
------------------


[0;31m---------------------------------------------------------------------------[0m
[0;31mAttributeError[0m                            Traceback (most recent call last)
Cell [0;32mIn[13], line 1[0m
[0;32m----> 1[0m [43mstate[49m[38;5;241;43m.[39;49m[43mreport[49m[38;5;241;43m.[39;49m[43mhistogram[49m(
[1;32m      2[0m     table_name[38;5;241m=[39m[38;5;124m"[39m[38;5;124mpersons[39m[38;5;124m"[39m, 
[1;32m      3[0m     column_name[38;5;241m=[39m[38;5;124m"[39m[38;5;124mdistance_to_school[39m[38;5;124m"[39m,
[1;32m      4[0m )

[0;31mAttributeError[0m: 'Reporting' object has no attribute 'histogram'

